{
 "cells": [
  {
   "cell_type": "markdown",
   "id": "79389913",
   "metadata": {},
   "source": [
    "Functions for Numpy"
   ]
  },
  {
   "cell_type": "code",
   "execution_count": 2,
   "id": "fb17c9b7",
   "metadata": {},
   "outputs": [],
   "source": [
    "import numpy as np"
   ]
  },
  {
   "cell_type": "code",
   "execution_count": 3,
   "id": "90f11c2c",
   "metadata": {},
   "outputs": [
    {
     "data": {
      "text/plain": [
       "array([0, 1, 2, 3])"
      ]
     },
     "execution_count": 3,
     "metadata": {},
     "output_type": "execute_result"
    }
   ],
   "source": [
    "np.arange(4)"
   ]
  },
  {
   "cell_type": "code",
   "execution_count": 4,
   "id": "97c5e37b",
   "metadata": {},
   "outputs": [
    {
     "data": {
      "text/plain": [
       "array([1, 1, 1, 1, 1, 1, 1, 1, 1, 1])"
      ]
     },
     "execution_count": 4,
     "metadata": {},
     "output_type": "execute_result"
    }
   ],
   "source": [
    "X=np.arange(10)\n",
    "np.ones_like(X)"
   ]
  },
  {
   "cell_type": "code",
   "execution_count": 7,
   "id": "651c900c",
   "metadata": {},
   "outputs": [
    {
     "data": {
      "text/plain": [
       "array([[1., 1., 1., 1., 1., 1., 1., 1., 1., 1.],\n",
       "       [1., 1., 1., 1., 1., 1., 1., 1., 1., 1.],\n",
       "       [1., 1., 1., 1., 1., 1., 1., 1., 1., 1.],\n",
       "       [1., 1., 1., 1., 1., 1., 1., 1., 1., 1.],\n",
       "       [1., 1., 1., 1., 1., 1., 1., 1., 1., 1.],\n",
       "       [1., 1., 1., 1., 1., 1., 1., 1., 1., 1.],\n",
       "       [1., 1., 1., 1., 1., 1., 1., 1., 1., 1.],\n",
       "       [1., 1., 1., 1., 1., 1., 1., 1., 1., 1.],\n",
       "       [1., 1., 1., 1., 1., 1., 1., 1., 1., 1.],\n",
       "       [1., 1., 1., 1., 1., 1., 1., 1., 1., 1.]])"
      ]
     },
     "execution_count": 7,
     "metadata": {},
     "output_type": "execute_result"
    }
   ],
   "source": [
    "np.ones([10,10])"
   ]
  },
  {
   "cell_type": "code",
   "execution_count": 8,
   "id": "5d76b342",
   "metadata": {},
   "outputs": [
    {
     "data": {
      "text/plain": [
       "array([24, 14, 37, 32, 41, 45, 39, 42, 21, 43, 46, 47, 11, 32, 11, 33, 41,\n",
       "       39, 34, 22, 47, 14, 12, 31, 27, 44, 31, 37, 28, 22, 12, 39, 34, 20,\n",
       "       40, 44, 16, 22, 44])"
      ]
     },
     "execution_count": 8,
     "metadata": {},
     "output_type": "execute_result"
    },
    {
     "name": "stderr",
     "output_type": "stream",
     "text": [
      "Exception in callback BaseSelectorEventLoop._read_from_self()\n",
      "handle: <Handle BaseSelectorEventLoop._read_from_self()>\n",
      "Traceback (most recent call last):\n",
      "  File \"C:\\Users\\Daniel\\anaconda3\\lib\\asyncio\\events.py\", line 81, in _run\n",
      "    self._context.run(self._callback, *self._args)\n",
      "  File \"C:\\Users\\Daniel\\anaconda3\\lib\\asyncio\\selector_events.py\", line 120, in _read_from_self\n",
      "    data = self._ssock.recv(4096)\n",
      "ConnectionResetError: [WinError 10054] Foi forçado o cancelamento de uma conexão existente pelo host remoto\n",
      "Exception in callback BaseSelectorEventLoop._read_from_self()\n",
      "handle: <Handle BaseSelectorEventLoop._read_from_self()>\n",
      "Traceback (most recent call last):\n",
      "  File \"C:\\Users\\Daniel\\anaconda3\\lib\\asyncio\\events.py\", line 81, in _run\n",
      "    self._context.run(self._callback, *self._args)\n",
      "  File \"C:\\Users\\Daniel\\anaconda3\\lib\\asyncio\\selector_events.py\", line 120, in _read_from_self\n",
      "    data = self._ssock.recv(4096)\n",
      "ConnectionResetError: [WinError 10054] Foi forçado o cancelamento de uma conexão existente pelo host remoto\n",
      "Exception in callback BaseSelectorEventLoop._read_from_self()\n",
      "handle: <Handle BaseSelectorEventLoop._read_from_self()>\n",
      "Traceback (most recent call last):\n",
      "  File \"C:\\Users\\Daniel\\anaconda3\\lib\\asyncio\\events.py\", line 81, in _run\n",
      "    self._context.run(self._callback, *self._args)\n",
      "  File \"C:\\Users\\Daniel\\anaconda3\\lib\\asyncio\\selector_events.py\", line 120, in _read_from_self\n",
      "    data = self._ssock.recv(4096)\n",
      "ConnectionResetError: [WinError 10054] Foi forçado o cancelamento de uma conexão existente pelo host remoto\n",
      "Exception in callback BaseSelectorEventLoop._read_from_self()\n",
      "handle: <Handle BaseSelectorEventLoop._read_from_self()>\n",
      "Traceback (most recent call last):\n",
      "  File \"C:\\Users\\Daniel\\anaconda3\\lib\\asyncio\\events.py\", line 81, in _run\n",
      "    self._context.run(self._callback, *self._args)\n",
      "  File \"C:\\Users\\Daniel\\anaconda3\\lib\\asyncio\\selector_events.py\", line 120, in _read_from_self\n",
      "    data = self._ssock.recv(4096)\n",
      "ConnectionResetError: [WinError 10054] Foi forçado o cancelamento de uma conexão existente pelo host remoto\n",
      "Exception in callback BaseSelectorEventLoop._read_from_self()\n",
      "handle: <Handle BaseSelectorEventLoop._read_from_self()>\n",
      "Traceback (most recent call last):\n",
      "  File \"C:\\Users\\Daniel\\anaconda3\\lib\\asyncio\\events.py\", line 81, in _run\n",
      "    self._context.run(self._callback, *self._args)\n",
      "  File \"C:\\Users\\Daniel\\anaconda3\\lib\\asyncio\\selector_events.py\", line 120, in _read_from_self\n",
      "    data = self._ssock.recv(4096)\n",
      "ConnectionResetError: [WinError 10054] Foi forçado o cancelamento de uma conexão existente pelo host remoto\n",
      "Exception in callback BaseSelectorEventLoop._read_from_self()\n",
      "handle: <Handle BaseSelectorEventLoop._read_from_self()>\n",
      "Traceback (most recent call last):\n",
      "  File \"C:\\Users\\Daniel\\anaconda3\\lib\\asyncio\\events.py\", line 81, in _run\n",
      "    self._context.run(self._callback, *self._args)\n",
      "  File \"C:\\Users\\Daniel\\anaconda3\\lib\\asyncio\\selector_events.py\", line 120, in _read_from_self\n",
      "    data = self._ssock.recv(4096)\n",
      "ConnectionResetError: [WinError 10054] Foi forçado o cancelamento de uma conexão existente pelo host remoto\n",
      "Exception in callback BaseSelectorEventLoop._read_from_self()\n",
      "handle: <Handle BaseSelectorEventLoop._read_from_self()>\n",
      "Traceback (most recent call last):\n",
      "  File \"C:\\Users\\Daniel\\anaconda3\\lib\\asyncio\\events.py\", line 81, in _run\n",
      "    self._context.run(self._callback, *self._args)\n",
      "  File \"C:\\Users\\Daniel\\anaconda3\\lib\\asyncio\\selector_events.py\", line 120, in _read_from_self\n",
      "    data = self._ssock.recv(4096)\n",
      "ConnectionResetError: [WinError 10054] Foi forçado o cancelamento de uma conexão existente pelo host remoto\n",
      "Exception in callback BaseSelectorEventLoop._read_from_self()\n",
      "handle: <Handle BaseSelectorEventLoop._read_from_self()>\n",
      "Traceback (most recent call last):\n",
      "  File \"C:\\Users\\Daniel\\anaconda3\\lib\\asyncio\\events.py\", line 81, in _run\n",
      "    self._context.run(self._callback, *self._args)\n",
      "  File \"C:\\Users\\Daniel\\anaconda3\\lib\\asyncio\\selector_events.py\", line 120, in _read_from_self\n",
      "    data = self._ssock.recv(4096)\n",
      "ConnectionResetError: [WinError 10054] Foi forçado o cancelamento de uma conexão existente pelo host remoto\n",
      "Exception in callback BaseSelectorEventLoop._read_from_self()\n",
      "handle: <Handle BaseSelectorEventLoop._read_from_self()>\n",
      "Traceback (most recent call last):\n",
      "  File \"C:\\Users\\Daniel\\anaconda3\\lib\\asyncio\\events.py\", line 81, in _run\n",
      "    self._context.run(self._callback, *self._args)\n",
      "  File \"C:\\Users\\Daniel\\anaconda3\\lib\\asyncio\\selector_events.py\", line 120, in _read_from_self\n",
      "    data = self._ssock.recv(4096)\n",
      "ConnectionResetError: [WinError 10054] Foi forçado o cancelamento de uma conexão existente pelo host remoto\n",
      "Exception in callback BaseSelectorEventLoop._read_from_self()\n",
      "handle: <Handle BaseSelectorEventLoop._read_from_self()>\n",
      "Traceback (most recent call last):\n",
      "  File \"C:\\Users\\Daniel\\anaconda3\\lib\\asyncio\\events.py\", line 81, in _run\n",
      "    self._context.run(self._callback, *self._args)\n",
      "  File \"C:\\Users\\Daniel\\anaconda3\\lib\\asyncio\\selector_events.py\", line 120, in _read_from_self\n",
      "    data = self._ssock.recv(4096)\n",
      "ConnectionResetError: [WinError 10054] Foi forçado o cancelamento de uma conexão existente pelo host remoto\n",
      "Exception in callback BaseSelectorEventLoop._read_from_self()\n",
      "handle: <Handle BaseSelectorEventLoop._read_from_self()>\n",
      "Traceback (most recent call last):\n",
      "  File \"C:\\Users\\Daniel\\anaconda3\\lib\\asyncio\\events.py\", line 81, in _run\n",
      "    self._context.run(self._callback, *self._args)\n",
      "  File \"C:\\Users\\Daniel\\anaconda3\\lib\\asyncio\\selector_events.py\", line 120, in _read_from_self\n",
      "    data = self._ssock.recv(4096)\n",
      "ConnectionResetError: [WinError 10054] Foi forçado o cancelamento de uma conexão existente pelo host remoto\n",
      "Exception in callback BaseSelectorEventLoop._read_from_self()\n",
      "handle: <Handle BaseSelectorEventLoop._read_from_self()>\n",
      "Traceback (most recent call last):\n",
      "  File \"C:\\Users\\Daniel\\anaconda3\\lib\\asyncio\\events.py\", line 81, in _run\n",
      "    self._context.run(self._callback, *self._args)\n",
      "  File \"C:\\Users\\Daniel\\anaconda3\\lib\\asyncio\\selector_events.py\", line 120, in _read_from_self\n",
      "    data = self._ssock.recv(4096)\n",
      "ConnectionResetError: [WinError 10054] Foi forçado o cancelamento de uma conexão existente pelo host remoto\n",
      "Exception in callback BaseSelectorEventLoop._read_from_self()\n",
      "handle: <Handle BaseSelectorEventLoop._read_from_self()>\n",
      "Traceback (most recent call last):\n",
      "  File \"C:\\Users\\Daniel\\anaconda3\\lib\\asyncio\\events.py\", line 81, in _run\n",
      "    self._context.run(self._callback, *self._args)\n",
      "  File \"C:\\Users\\Daniel\\anaconda3\\lib\\asyncio\\selector_events.py\", line 120, in _read_from_self\n",
      "    data = self._ssock.recv(4096)\n",
      "ConnectionResetError: [WinError 10054] Foi forçado o cancelamento de uma conexão existente pelo host remoto\n",
      "Exception in callback BaseSelectorEventLoop._read_from_self()\n",
      "handle: <Handle BaseSelectorEventLoop._read_from_self()>\n",
      "Traceback (most recent call last):\n",
      "  File \"C:\\Users\\Daniel\\anaconda3\\lib\\asyncio\\events.py\", line 81, in _run\n",
      "    self._context.run(self._callback, *self._args)\n",
      "  File \"C:\\Users\\Daniel\\anaconda3\\lib\\asyncio\\selector_events.py\", line 120, in _read_from_self\n",
      "    data = self._ssock.recv(4096)\n",
      "ConnectionResetError: [WinError 10054] Foi forçado o cancelamento de uma conexão existente pelo host remoto\n",
      "Exception in callback BaseSelectorEventLoop._read_from_self()\n",
      "handle: <Handle BaseSelectorEventLoop._read_from_self()>\n",
      "Traceback (most recent call last):\n",
      "  File \"C:\\Users\\Daniel\\anaconda3\\lib\\asyncio\\events.py\", line 81, in _run\n",
      "    self._context.run(self._callback, *self._args)\n",
      "  File \"C:\\Users\\Daniel\\anaconda3\\lib\\asyncio\\selector_events.py\", line 120, in _read_from_self\n",
      "    data = self._ssock.recv(4096)\n",
      "ConnectionResetError: [WinError 10054] Foi forçado o cancelamento de uma conexão existente pelo host remoto\n",
      "Exception in callback BaseSelectorEventLoop._read_from_self()\n",
      "handle: <Handle BaseSelectorEventLoop._read_from_self()>\n",
      "Traceback (most recent call last):\n",
      "  File \"C:\\Users\\Daniel\\anaconda3\\lib\\asyncio\\events.py\", line 81, in _run\n",
      "    self._context.run(self._callback, *self._args)\n",
      "  File \"C:\\Users\\Daniel\\anaconda3\\lib\\asyncio\\selector_events.py\", line 120, in _read_from_self\n",
      "    data = self._ssock.recv(4096)\n",
      "ConnectionResetError: [WinError 10054] Foi forçado o cancelamento de uma conexão existente pelo host remoto\n"
     ]
    },
    {
     "name": "stderr",
     "output_type": "stream",
     "text": [
      "Exception in callback BaseSelectorEventLoop._read_from_self()\n",
      "handle: <Handle BaseSelectorEventLoop._read_from_self()>\n",
      "Traceback (most recent call last):\n",
      "  File \"C:\\Users\\Daniel\\anaconda3\\lib\\asyncio\\events.py\", line 81, in _run\n",
      "    self._context.run(self._callback, *self._args)\n",
      "  File \"C:\\Users\\Daniel\\anaconda3\\lib\\asyncio\\selector_events.py\", line 120, in _read_from_self\n",
      "    data = self._ssock.recv(4096)\n",
      "ConnectionResetError: [WinError 10054] Foi forçado o cancelamento de uma conexão existente pelo host remoto\n",
      "Exception in callback BaseSelectorEventLoop._read_from_self()\n",
      "handle: <Handle BaseSelectorEventLoop._read_from_self()>\n",
      "Traceback (most recent call last):\n",
      "  File \"C:\\Users\\Daniel\\anaconda3\\lib\\asyncio\\events.py\", line 81, in _run\n",
      "    self._context.run(self._callback, *self._args)\n",
      "  File \"C:\\Users\\Daniel\\anaconda3\\lib\\asyncio\\selector_events.py\", line 120, in _read_from_self\n",
      "    data = self._ssock.recv(4096)\n",
      "ConnectionResetError: [WinError 10054] Foi forçado o cancelamento de uma conexão existente pelo host remoto\n",
      "Exception in callback BaseSelectorEventLoop._read_from_self()\n",
      "handle: <Handle BaseSelectorEventLoop._read_from_self()>\n",
      "Traceback (most recent call last):\n",
      "  File \"C:\\Users\\Daniel\\anaconda3\\lib\\asyncio\\events.py\", line 81, in _run\n",
      "    self._context.run(self._callback, *self._args)\n",
      "  File \"C:\\Users\\Daniel\\anaconda3\\lib\\asyncio\\selector_events.py\", line 120, in _read_from_self\n",
      "    data = self._ssock.recv(4096)\n",
      "ConnectionResetError: [WinError 10054] Foi forçado o cancelamento de uma conexão existente pelo host remoto\n",
      "Exception in callback BaseSelectorEventLoop._read_from_self()\n",
      "handle: <Handle BaseSelectorEventLoop._read_from_self()>\n",
      "Traceback (most recent call last):\n",
      "  File \"C:\\Users\\Daniel\\anaconda3\\lib\\asyncio\\events.py\", line 81, in _run\n",
      "    self._context.run(self._callback, *self._args)\n",
      "  File \"C:\\Users\\Daniel\\anaconda3\\lib\\asyncio\\selector_events.py\", line 120, in _read_from_self\n",
      "    data = self._ssock.recv(4096)\n",
      "ConnectionResetError: [WinError 10054] Foi forçado o cancelamento de uma conexão existente pelo host remoto\n",
      "Exception in callback BaseSelectorEventLoop._read_from_self()\n",
      "handle: <Handle BaseSelectorEventLoop._read_from_self()>\n",
      "Traceback (most recent call last):\n",
      "  File \"C:\\Users\\Daniel\\anaconda3\\lib\\asyncio\\events.py\", line 81, in _run\n",
      "    self._context.run(self._callback, *self._args)\n",
      "  File \"C:\\Users\\Daniel\\anaconda3\\lib\\asyncio\\selector_events.py\", line 120, in _read_from_self\n",
      "    data = self._ssock.recv(4096)\n",
      "ConnectionResetError: [WinError 10054] Foi forçado o cancelamento de uma conexão existente pelo host remoto\n",
      "Exception in callback BaseSelectorEventLoop._read_from_self()\n",
      "handle: <Handle BaseSelectorEventLoop._read_from_self()>\n",
      "Traceback (most recent call last):\n",
      "  File \"C:\\Users\\Daniel\\anaconda3\\lib\\asyncio\\events.py\", line 81, in _run\n",
      "    self._context.run(self._callback, *self._args)\n",
      "  File \"C:\\Users\\Daniel\\anaconda3\\lib\\asyncio\\selector_events.py\", line 120, in _read_from_self\n",
      "    data = self._ssock.recv(4096)\n",
      "ConnectionResetError: [WinError 10054] Foi forçado o cancelamento de uma conexão existente pelo host remoto\n",
      "Exception in callback BaseSelectorEventLoop._read_from_self()\n",
      "handle: <Handle BaseSelectorEventLoop._read_from_self()>\n",
      "Traceback (most recent call last):\n",
      "  File \"C:\\Users\\Daniel\\anaconda3\\lib\\asyncio\\events.py\", line 81, in _run\n",
      "    self._context.run(self._callback, *self._args)\n",
      "  File \"C:\\Users\\Daniel\\anaconda3\\lib\\asyncio\\selector_events.py\", line 120, in _read_from_self\n",
      "    data = self._ssock.recv(4096)\n",
      "ConnectionResetError: [WinError 10054] Foi forçado o cancelamento de uma conexão existente pelo host remoto\n",
      "Exception in callback BaseSelectorEventLoop._read_from_self()\n",
      "handle: <Handle BaseSelectorEventLoop._read_from_self()>\n",
      "Traceback (most recent call last):\n",
      "  File \"C:\\Users\\Daniel\\anaconda3\\lib\\asyncio\\events.py\", line 81, in _run\n",
      "    self._context.run(self._callback, *self._args)\n",
      "  File \"C:\\Users\\Daniel\\anaconda3\\lib\\asyncio\\selector_events.py\", line 120, in _read_from_self\n",
      "    data = self._ssock.recv(4096)\n",
      "ConnectionResetError: [WinError 10054] Foi forçado o cancelamento de uma conexão existente pelo host remoto\n",
      "Exception in callback BaseSelectorEventLoop._read_from_self()\n",
      "handle: <Handle BaseSelectorEventLoop._read_from_self()>\n",
      "Traceback (most recent call last):\n",
      "  File \"C:\\Users\\Daniel\\anaconda3\\lib\\asyncio\\events.py\", line 81, in _run\n",
      "    self._context.run(self._callback, *self._args)\n",
      "  File \"C:\\Users\\Daniel\\anaconda3\\lib\\asyncio\\selector_events.py\", line 120, in _read_from_self\n",
      "    data = self._ssock.recv(4096)\n",
      "ConnectionResetError: [WinError 10054] Foi forçado o cancelamento de uma conexão existente pelo host remoto\n",
      "Exception in callback BaseSelectorEventLoop._read_from_self()\n",
      "handle: <Handle BaseSelectorEventLoop._read_from_self()>\n",
      "Traceback (most recent call last):\n",
      "  File \"C:\\Users\\Daniel\\anaconda3\\lib\\asyncio\\events.py\", line 81, in _run\n",
      "    self._context.run(self._callback, *self._args)\n",
      "  File \"C:\\Users\\Daniel\\anaconda3\\lib\\asyncio\\selector_events.py\", line 120, in _read_from_self\n",
      "    data = self._ssock.recv(4096)\n",
      "ConnectionResetError: [WinError 10054] Foi forçado o cancelamento de uma conexão existente pelo host remoto\n",
      "Exception in callback BaseSelectorEventLoop._read_from_self()\n",
      "handle: <Handle BaseSelectorEventLoop._read_from_self()>\n",
      "Traceback (most recent call last):\n",
      "  File \"C:\\Users\\Daniel\\anaconda3\\lib\\asyncio\\events.py\", line 81, in _run\n",
      "    self._context.run(self._callback, *self._args)\n",
      "  File \"C:\\Users\\Daniel\\anaconda3\\lib\\asyncio\\selector_events.py\", line 120, in _read_from_self\n",
      "    data = self._ssock.recv(4096)\n",
      "ConnectionResetError: [WinError 10054] Foi forçado o cancelamento de uma conexão existente pelo host remoto\n",
      "Exception in callback BaseSelectorEventLoop._read_from_self()\n",
      "handle: <Handle BaseSelectorEventLoop._read_from_self()>\n",
      "Traceback (most recent call last):\n",
      "  File \"C:\\Users\\Daniel\\anaconda3\\lib\\asyncio\\events.py\", line 81, in _run\n",
      "    self._context.run(self._callback, *self._args)\n",
      "  File \"C:\\Users\\Daniel\\anaconda3\\lib\\asyncio\\selector_events.py\", line 120, in _read_from_self\n",
      "    data = self._ssock.recv(4096)\n",
      "ConnectionResetError: [WinError 10054] Foi forçado o cancelamento de uma conexão existente pelo host remoto\n",
      "Exception in callback BaseSelectorEventLoop._read_from_self()\n",
      "handle: <Handle BaseSelectorEventLoop._read_from_self()>\n",
      "Traceback (most recent call last):\n",
      "  File \"C:\\Users\\Daniel\\anaconda3\\lib\\asyncio\\events.py\", line 81, in _run\n",
      "    self._context.run(self._callback, *self._args)\n",
      "  File \"C:\\Users\\Daniel\\anaconda3\\lib\\asyncio\\selector_events.py\", line 120, in _read_from_self\n",
      "    data = self._ssock.recv(4096)\n",
      "ConnectionResetError: [WinError 10054] Foi forçado o cancelamento de uma conexão existente pelo host remoto\n",
      "Exception in callback BaseSelectorEventLoop._read_from_self()\n",
      "handle: <Handle BaseSelectorEventLoop._read_from_self()>\n",
      "Traceback (most recent call last):\n",
      "  File \"C:\\Users\\Daniel\\anaconda3\\lib\\asyncio\\events.py\", line 81, in _run\n",
      "    self._context.run(self._callback, *self._args)\n",
      "  File \"C:\\Users\\Daniel\\anaconda3\\lib\\asyncio\\selector_events.py\", line 120, in _read_from_self\n",
      "    data = self._ssock.recv(4096)\n",
      "ConnectionResetError: [WinError 10054] Foi forçado o cancelamento de uma conexão existente pelo host remoto\n",
      "Exception in callback BaseSelectorEventLoop._read_from_self()\n",
      "handle: <Handle BaseSelectorEventLoop._read_from_self()>\n",
      "Traceback (most recent call last):\n",
      "  File \"C:\\Users\\Daniel\\anaconda3\\lib\\asyncio\\events.py\", line 81, in _run\n",
      "    self._context.run(self._callback, *self._args)\n",
      "  File \"C:\\Users\\Daniel\\anaconda3\\lib\\asyncio\\selector_events.py\", line 120, in _read_from_self\n",
      "    data = self._ssock.recv(4096)\n",
      "ConnectionResetError: [WinError 10054] Foi forçado o cancelamento de uma conexão existente pelo host remoto\n",
      "Exception in callback BaseSelectorEventLoop._read_from_self()\n",
      "handle: <Handle BaseSelectorEventLoop._read_from_self()>\n",
      "Traceback (most recent call last):\n",
      "  File \"C:\\Users\\Daniel\\anaconda3\\lib\\asyncio\\events.py\", line 81, in _run\n",
      "    self._context.run(self._callback, *self._args)\n",
      "  File \"C:\\Users\\Daniel\\anaconda3\\lib\\asyncio\\selector_events.py\", line 120, in _read_from_self\n",
      "    data = self._ssock.recv(4096)\n",
      "ConnectionResetError: [WinError 10054] Foi forçado o cancelamento de uma conexão existente pelo host remoto\n"
     ]
    },
    {
     "name": "stderr",
     "output_type": "stream",
     "text": [
      "Exception in callback BaseSelectorEventLoop._read_from_self()\n",
      "handle: <Handle BaseSelectorEventLoop._read_from_self()>\n",
      "Traceback (most recent call last):\n",
      "  File \"C:\\Users\\Daniel\\anaconda3\\lib\\asyncio\\events.py\", line 81, in _run\n",
      "    self._context.run(self._callback, *self._args)\n",
      "  File \"C:\\Users\\Daniel\\anaconda3\\lib\\asyncio\\selector_events.py\", line 120, in _read_from_self\n",
      "    data = self._ssock.recv(4096)\n",
      "ConnectionResetError: [WinError 10054] Foi forçado o cancelamento de uma conexão existente pelo host remoto\n",
      "Exception in callback BaseSelectorEventLoop._read_from_self()\n",
      "handle: <Handle BaseSelectorEventLoop._read_from_self()>\n",
      "Traceback (most recent call last):\n",
      "  File \"C:\\Users\\Daniel\\anaconda3\\lib\\asyncio\\events.py\", line 81, in _run\n",
      "    self._context.run(self._callback, *self._args)\n",
      "  File \"C:\\Users\\Daniel\\anaconda3\\lib\\asyncio\\selector_events.py\", line 120, in _read_from_self\n",
      "    data = self._ssock.recv(4096)\n",
      "ConnectionResetError: [WinError 10054] Foi forçado o cancelamento de uma conexão existente pelo host remoto\n",
      "Exception in callback BaseSelectorEventLoop._read_from_self()\n",
      "handle: <Handle BaseSelectorEventLoop._read_from_self()>\n",
      "Traceback (most recent call last):\n",
      "  File \"C:\\Users\\Daniel\\anaconda3\\lib\\asyncio\\events.py\", line 81, in _run\n",
      "    self._context.run(self._callback, *self._args)\n",
      "  File \"C:\\Users\\Daniel\\anaconda3\\lib\\asyncio\\selector_events.py\", line 120, in _read_from_self\n",
      "    data = self._ssock.recv(4096)\n",
      "ConnectionResetError: [WinError 10054] Foi forçado o cancelamento de uma conexão existente pelo host remoto\n",
      "Exception in callback BaseSelectorEventLoop._read_from_self()\n",
      "handle: <Handle BaseSelectorEventLoop._read_from_self()>\n",
      "Traceback (most recent call last):\n",
      "  File \"C:\\Users\\Daniel\\anaconda3\\lib\\asyncio\\events.py\", line 81, in _run\n",
      "    self._context.run(self._callback, *self._args)\n",
      "  File \"C:\\Users\\Daniel\\anaconda3\\lib\\asyncio\\selector_events.py\", line 120, in _read_from_self\n",
      "    data = self._ssock.recv(4096)\n",
      "ConnectionResetError: [WinError 10054] Foi forçado o cancelamento de uma conexão existente pelo host remoto\n",
      "Exception in callback BaseSelectorEventLoop._read_from_self()\n",
      "handle: <Handle BaseSelectorEventLoop._read_from_self()>\n",
      "Traceback (most recent call last):\n",
      "  File \"C:\\Users\\Daniel\\anaconda3\\lib\\asyncio\\events.py\", line 81, in _run\n",
      "    self._context.run(self._callback, *self._args)\n",
      "  File \"C:\\Users\\Daniel\\anaconda3\\lib\\asyncio\\selector_events.py\", line 120, in _read_from_self\n",
      "    data = self._ssock.recv(4096)\n",
      "ConnectionResetError: [WinError 10054] Foi forçado o cancelamento de uma conexão existente pelo host remoto\n",
      "Exception in callback BaseSelectorEventLoop._read_from_self()\n",
      "handle: <Handle BaseSelectorEventLoop._read_from_self()>\n",
      "Traceback (most recent call last):\n",
      "  File \"C:\\Users\\Daniel\\anaconda3\\lib\\asyncio\\events.py\", line 81, in _run\n",
      "    self._context.run(self._callback, *self._args)\n",
      "  File \"C:\\Users\\Daniel\\anaconda3\\lib\\asyncio\\selector_events.py\", line 120, in _read_from_self\n",
      "    data = self._ssock.recv(4096)\n",
      "ConnectionResetError: [WinError 10054] Foi forçado o cancelamento de uma conexão existente pelo host remoto\n",
      "Exception in callback BaseSelectorEventLoop._read_from_self()\n",
      "handle: <Handle BaseSelectorEventLoop._read_from_self()>\n",
      "Traceback (most recent call last):\n",
      "  File \"C:\\Users\\Daniel\\anaconda3\\lib\\asyncio\\events.py\", line 81, in _run\n",
      "    self._context.run(self._callback, *self._args)\n",
      "  File \"C:\\Users\\Daniel\\anaconda3\\lib\\asyncio\\selector_events.py\", line 120, in _read_from_self\n",
      "    data = self._ssock.recv(4096)\n",
      "ConnectionResetError: [WinError 10054] Foi forçado o cancelamento de uma conexão existente pelo host remoto\n",
      "Exception in callback BaseSelectorEventLoop._read_from_self()\n",
      "handle: <Handle BaseSelectorEventLoop._read_from_self()>\n",
      "Traceback (most recent call last):\n",
      "  File \"C:\\Users\\Daniel\\anaconda3\\lib\\asyncio\\events.py\", line 81, in _run\n",
      "    self._context.run(self._callback, *self._args)\n",
      "  File \"C:\\Users\\Daniel\\anaconda3\\lib\\asyncio\\selector_events.py\", line 120, in _read_from_self\n",
      "    data = self._ssock.recv(4096)\n",
      "ConnectionResetError: [WinError 10054] Foi forçado o cancelamento de uma conexão existente pelo host remoto\n",
      "Exception in callback BaseSelectorEventLoop._read_from_self()\n",
      "handle: <Handle BaseSelectorEventLoop._read_from_self()>\n",
      "Traceback (most recent call last):\n",
      "  File \"C:\\Users\\Daniel\\anaconda3\\lib\\asyncio\\events.py\", line 81, in _run\n",
      "    self._context.run(self._callback, *self._args)\n",
      "  File \"C:\\Users\\Daniel\\anaconda3\\lib\\asyncio\\selector_events.py\", line 120, in _read_from_self\n",
      "    data = self._ssock.recv(4096)\n",
      "ConnectionResetError: [WinError 10054] Foi forçado o cancelamento de uma conexão existente pelo host remoto\n",
      "Exception in callback BaseSelectorEventLoop._read_from_self()\n",
      "handle: <Handle BaseSelectorEventLoop._read_from_self()>\n",
      "Traceback (most recent call last):\n",
      "  File \"C:\\Users\\Daniel\\anaconda3\\lib\\asyncio\\events.py\", line 81, in _run\n",
      "    self._context.run(self._callback, *self._args)\n",
      "  File \"C:\\Users\\Daniel\\anaconda3\\lib\\asyncio\\selector_events.py\", line 120, in _read_from_self\n",
      "    data = self._ssock.recv(4096)\n",
      "ConnectionResetError: [WinError 10054] Foi forçado o cancelamento de uma conexão existente pelo host remoto\n",
      "Exception in callback BaseSelectorEventLoop._read_from_self()\n",
      "handle: <Handle BaseSelectorEventLoop._read_from_self()>\n",
      "Traceback (most recent call last):\n",
      "  File \"C:\\Users\\Daniel\\anaconda3\\lib\\asyncio\\events.py\", line 81, in _run\n",
      "    self._context.run(self._callback, *self._args)\n",
      "  File \"C:\\Users\\Daniel\\anaconda3\\lib\\asyncio\\selector_events.py\", line 120, in _read_from_self\n",
      "    data = self._ssock.recv(4096)\n",
      "ConnectionResetError: [WinError 10054] Foi forçado o cancelamento de uma conexão existente pelo host remoto\n",
      "Exception in callback BaseSelectorEventLoop._read_from_self()\n",
      "handle: <Handle BaseSelectorEventLoop._read_from_self()>\n",
      "Traceback (most recent call last):\n",
      "  File \"C:\\Users\\Daniel\\anaconda3\\lib\\asyncio\\events.py\", line 81, in _run\n",
      "    self._context.run(self._callback, *self._args)\n",
      "  File \"C:\\Users\\Daniel\\anaconda3\\lib\\asyncio\\selector_events.py\", line 120, in _read_from_self\n",
      "    data = self._ssock.recv(4096)\n",
      "ConnectionResetError: [WinError 10054] Foi forçado o cancelamento de uma conexão existente pelo host remoto\n",
      "Exception in callback BaseSelectorEventLoop._read_from_self()\n",
      "handle: <Handle BaseSelectorEventLoop._read_from_self()>\n",
      "Traceback (most recent call last):\n",
      "  File \"C:\\Users\\Daniel\\anaconda3\\lib\\asyncio\\events.py\", line 81, in _run\n",
      "    self._context.run(self._callback, *self._args)\n",
      "  File \"C:\\Users\\Daniel\\anaconda3\\lib\\asyncio\\selector_events.py\", line 120, in _read_from_self\n",
      "    data = self._ssock.recv(4096)\n",
      "ConnectionResetError: [WinError 10054] Foi forçado o cancelamento de uma conexão existente pelo host remoto\n"
     ]
    }
   ],
   "source": [
    "np.random.randint(10,49,size=(39,))"
   ]
  },
  {
   "cell_type": "code",
   "execution_count": null,
   "id": "8a0293df",
   "metadata": {},
   "outputs": [],
   "source": []
  }
 ],
 "metadata": {
  "kernelspec": {
   "display_name": "Python 3",
   "language": "python",
   "name": "python3"
  },
  "language_info": {
   "codemirror_mode": {
    "name": "ipython",
    "version": 3
   },
   "file_extension": ".py",
   "mimetype": "text/x-python",
   "name": "python",
   "nbconvert_exporter": "python",
   "pygments_lexer": "ipython3",
   "version": "3.8.8"
  }
 },
 "nbformat": 4,
 "nbformat_minor": 5
}
